#include <iostream>
using namespace std;
int main(){

try
{

cout<<"We are in try block";

divide(20,10,30);

divide(10,10,30);

}

catch (int i)

{

cout<<"Caught Exception";

}

return 0;

}
int main(){

try{

cout<<"We are in try block";

divide(20,10,30);

divide(10,10,30);

}

catch (int i)

{

cout<<"Caught Exception";

}

return 0;

}